Workbook

Sheet AGENDA GENERAL CON CANDIDATOS
A1: BOGOTÁ | B1: LOCALIDAD | C1: SEDE | D1: HORA | E1: ACTIVIDAD | F1: ESTRATEGIA | G1: MES | H1: DIA | I1: FECHA CAMPAÑA | J1: DETALLE DE LA ACTIVIDAD | K1: LOGROS JUSTIFICACION | L1: DIRECCIÓN | M1: LINK DE GOOGLE MAPS | N1: COORDENADAS | O1: BARRIO | P1: BENEFICIARIOS O ASISTENTES | Q1: LÍDER Y CELULAR | R1: LOGISTICA (Vecinos contactados, espacio, sillas, publicidad, refrigerios)
A2: SUR | B2: BOGOTA. D.C. - LOCALIDAD 8 KENNEDY | C2: Kennedy Central | D2: 10:00 AM | E2: TERRITORIO | F2: POLITICO COMUNITARIA | G2: Diciembre | H2: =TEXT(I2,"dddd") -> lunes | I2: 45999 | J2: Lanzamiento de campaña en Kennedy | L2: Templo Kennedy Central
A3: SUR | B3: BOGOTA. D.C. - LOCALIDAD 8 KENNEDY | C3: Class | D3: 10:00 AM | E3: TERRITORIO | F3: POLITICO COMUNITARIA | G3: Diciembre | H3: =TEXT(I3,"dddd") -> lunes | I3: 45999 | J3: Lanzamiento de campaña en Kennedy | L3: Templo Class
A4: SUR | B4: BOGOTA. D.C. - LOCALIDAD 8 KENNEDY | C4: Patio Bonito | D4: 10:00 AM | E4: TERRITORIO | F4: POLITICO COMUNITARIA | G4: Diciembre | H4: =TEXT(I4,"dddd") -> lunes | I4: 45999 | J4: Lanzamiento de campaña en Kennedy | L4: Templo Patio Bonito
A5: SUR | B5: BOGOTA. D.C. - LOCALIDAD 8 KENNEDY | C5: Patio Bonito | D5: 8:00 PM | E5: SEGUIMIENTO | F5: POLITICO COMUNITARIA | G5: Diciembre | H5: =TEXT(I5,"dddd") -> jueves | I5: 45995 | J5: Reunión con líderes Patio Bonito para seguimiento de preparativos de reuniones campaña 13 de diciembre | K5: Reunión con líderes Patio Bonito para seguimiento de preparativos de reuniones campaña 13 de diciembre | L5: Virtual | M5: Virtual | N5: Virtual | O5: Virtual | P5: 0 | Q5: Hamilton Liz (Delegado Político)
A6: SUR | B6: BOGOTA. D.C. - LOCALIDAD 8 KENNEDY | C6: Kennedy Central | D6: 9:00 PM | E6: SEGUIMIENTO | F6: POLITICO COMUNITARIA | G6: Diciembre | H6: =TEXT(I6,"dddd") -> jueves | I6: 45995 | J6: Reunión con líderes Kennedy Central para seguimiento de preparativos de reuniones campaña 14 de diciembre | K6: Reunión con líderes Kennedy Central para seguimiento de preparativos de reuniones campaña 14 de diciembre | L6: Virtual | M6: Virtual | N6: Virtual | O6: Virtual | P6: 0 | Q6: Jenny García (Delegado Político)
A7: SUR | B7: BOGOTA. D.C. - LOCALIDAD 8 KENNEDY | C7: Carvajal | D7: 8:00 PM | E7: SEGUIMIENTO | F7: POLITICO COMUNITARIA | G7: Diciembre | H7: =TEXT(I7,"dddd") -> martes | I7: 46000 | J7: Reunión con líderes Carvajal para seguimiento de preparativos de reuniones campaña 16 de diciembre | K7: Reunión con líderes Kennedy Central para seguimiento de preparativos de reuniones campaña 16 de diciembre | L7: Virtual | M7: Virtual | N7: Virtual | O7: Virtual | P7: 0 | Q7: Sergio Osorio (Delagado Político)
A8: SUR | B8: BOGOTA. D.C. - LOCALIDAD 8 KENNEDY | C8: Patio Bonito | D8: 11:00AM | E8: TERRITORIO | F8: POLITICO COMUNITARIA | G8: Diciembre | H8: =TEXT(I8,"dddd") -> sábado | I8: 46004 | J8: MT - VILLA HERMOSA MALLA VIAL (3822) Reunión con vecinos del sector + MT - VILLA HERMOSA TAPAS TELECOMUNICACIONES | K8: 1. La vía fue incluida en un contrato para mantenimiento. 2. Se realiza intervención con jornada de embellecimiento para mitigar el punto critico, con el apoyo de la Alcaldía Local de Kennedy. 3, Se logro colocar tapa de comunicaciones que llevaba muhchos años, geneando gran riesgo | L8: Cra. 87f #40-28 | M8: google.com/maps/place/Casa+Hamilton/@4.6348379,-74.168413,3a,75y,207.37h,90t/data=!3m5!1e1!3m3!1sYHLoVj54sjcWE-C48KDXpQ!2e0!6shttps:%2F%2Fstreetviewpixels-pa.googleapis.com%2Fv1%2Fthumbnail%3Fcb_client%3Dmaps_sv.tactile%26w%3D900%26h%3D600%26pitch%3D0%26panoid%3DYHLoVj54sjcWE-C48KDXpQ%26yaw%3D207.36768!4m14!1m7!3m6!1s0x8e3f9d766b7b07b1:0x84c12dc578b81adc!2sCasa+Hamilton!8m2!3d4.6348284!4d-74.168418!16s%2Fg%2F11fl0wbbvf!3m5!1s0x8e3f9d766b7b07b1:0x84c12dc578b81adc!8m2!3d4.6348284!4d-74.168418!16s%2Fg%2F11fl0wbbvf?entry=ttu&g_ep=EgoyMDI1MTEyMy4xIKXMDSoASAFQAw%3D%3D | N8: 4.635074351599803, -74.16845019045742 | O8: Villa Hermosa | P8: 25 | Q8: Paula Alarcón (3504846700)
A9: SUR | B9: BOGOTA. D.C. - LOCALIDAD 8 KENNEDY | C9: Patio Bonito | D9: 12:30 M | E9: ALMUERZO | F9: N/A | G9: Diciembre | H9: =TEXT(I9,"dddd") -> sábado | I9: 46004 | J9: Almuerzo | K9: Restaurante desayunadero de la 87 en el segundo piso (al frente del CAI Patio Bonito) | L9: calle 26 sur con carrera 87 | M9: https://www.google.com/maps/@4.6389535,-74.1608905,3a,22.8y,177.68h,99.58t/data=!3m7!1e1!3m5!1sGuilCb6sP05z17gXhzckHQ!2e0!6shttps:%2F%2Fstreetviewpixels-pa.googleapis.com%2Fv1%2Fthumbnail%3Fcb_client%3Dmaps_sv.tactile%26w%3D900%26h%3D600%26pitch%3D-9.575314414106757%26panoid%3DGuilCb6sP05z17gXhzckHQ%26yaw%3D177.68235465223438!7i16384!8i8192?entry=ttu&g_ep=EgoyMDI1MTEyMy4xIKXMDSoASAFQAw%3D%3D | N9: 4.638945840164796, -74.1609951750653 | O9: Patio Bonito | Q9: Hamilton Liz (Delegado Político)
A10: SUR | B10: BOGOTA. D.C. - LOCALIDAD 8 KENNEDY | C10: Patio Bonito | D10: 2:00PM | E10: TERRITORIO | F10: POLITICO COMUNITARIA | G10: Diciembre | H10: =TEXT(I10,"dddd") -> sábado | I10: 46004 | J10: MT - CIUDADELA PRIMAVERA MALLA VIAL Y CANCHA (248) | K10: 1. Calle 6ta 2. Mantenimiento de cancha | L10: Cra. 91c #2-90 | M10: https://www.google.com/maps/@4.6389535,-74.1608905,3a,22.8y,177.68h,99.58t/data=!3m7!1e1!3m5!1sGuilCb6sP05z17gXhzckHQ!2e0!6shttps:%2F%2Fstreetviewpixels-pa.googleapis.com%2Fv1%2Fthumbnail%3Fcb_client%3Dmaps_sv.tactile%26w%3D900%26h%3D600%26pitch%3D-9.575314414106757%26panoid%3DGuilCb6sP05z17gXhzckHQ%26yaw%3D177.68235465223438!7i16384!8i8192?entry=ttu&g_ep=EgoyMDI1MTEyMy4xIKXMDSoASAFQAw%3D%3D | N10: 4.638945840164796, -74.1609951750653 | O10: Ciudadela Primavera | P10: 30 | Q10: Ana Temilda Guerrero (3124899155)
A11: SUR | B11: BOGOTA. D.C. - LOCALIDAD 8 KENNEDY | C11: Patio Bonito | D11: 4:00PM | E11: TERRITORIO | F11: POLITICO COMUNITARIA | G11: Diciembre | H11: =TEXT(I11,"dddd") -> sábado | I11: 46004 | J11: MT - TINTAL BASURAS PUNTO CRITICO (2738) | K11: 1. Se realiza intervención con jornada de embellecimiento para mitigar el punto critico, con el apoyo de la Alcaldía Local de Kennedy. 2, Jornada Opam con más de 60 beneficiados | L11: Calle 6d # 88d - 82 Salon Santa Fe 2 | M11: https://www.google.com/maps/place/Centro+Comercial+Ciudad+Tintal/@4.6484322,-74.1566005,3a,75y,259.88h,91.84t/data=!3m7!1e1!3m5!1sPvz2ZZ_LEPMtw1hCPni5xw!2e0!6shttps:%2F%2Fstreetviewpixels-pa.googleapis.com%2Fv1%2Fthumbnail%3Fcb_client%3Dmaps_sv.tactile%26w%3D900%26h%3D600%26pitch%3D-1.8368268512086843%26panoid%3DPvz2ZZ_LEPMtw1hCPni5xw%26yaw%3D259.882344672206!7i16384!8i8192!4m10!1m2!2m1!1sciudad+tintal!3m6!1s0x8e3f9c48a6b9e475:0xb493c62a8721eed2!8m2!3d4.6525882!4d-74.1601199!15sCg1jaXVkYWQgdGludGFskgEPc2hvcHBpbmdfY2VudGVy4AEA!16s%2Fg%2F1ptxhhfkq?entry=ttu&g_ep=EgoyMDI1MTEyMy4xIKXMDSoASAFQAw%3D%3D | N11: 4.652533182459536, -74.15123604371226 | O11: Tintal | P11: 20 | Q11: Luz Elena Garzón ( 3144359628)
A12: SUR | B12: BOGOTA. D.C. - LOCALIDAD 8 KENNEDY | C12: Kennedy Central | D12: 8:00 AM | E12: ENSEÑANZA | F12: AFINIDAD | G12: Diciembre | H12: Domingo | I12: 46005 | J12: Reunion de Afinidad Objetivo Que los hnos puedan compartir con nuestros representantes, y ellos puedan motivarlos a activar sus referidos y a participar activamente del bingo Logística Invitar a los hnos para que al finalizar el culto suban, Enviaremos una invitación a los líderes que tienen menos de 5 referidos para que asistan Contaremos con sonido y cabina con micrófono En el televisor se proyectarán videos de la leyes del partido, para que mientras nuestros representantes suban puedan los asistentes verlos Activación de líderes, en info mira | L12: AV CR 80 NO 42C 83 SUR | M12: 4.622006495658455, -74.16497448186743 | N12: google.com/maps/place/Iglesia+de+Dios+Ministerial+de+Jesucristo+Internacional+-+IDMJI+-+CGMJI+BTA+EL+OLIVO/@4.6215758,-74.164928,3a,75y,316.8h,90t/data=!3m7!1e1!3m5!1sJwIftdN6Rl-LMLqtdi_3Nw!2e0!6shttps:%2F%2Fstreetviewpixels-pa.googleapis.com%2Fv1%2Fthumbnail%3Fcb_client%3Dmaps_sv.tactile%26w%3D900%26h%3D600%26pitch%3D0%26panoid%3DJwIftdN6Rl-LMLqtdi_3Nw%26yaw%3D316.80283!7i16384!8i8192!4m14!1m7!3m6!1s0x8e3f9e842a6a8335:0xe8f39c19a9ab6da3!2sIglesia+de+Dios+Ministerial+de+Jesucristo+Internacional+-+IDMJI+-+CGMJI+BTA+EL+OLIVO!8m2!3d4.6216536!4d-74.1650013!16s%2Fg%2F1tdksvtw!3m5!1s0x8e3f9e842a6a8335:0xe8f39c19a9ab6da3!8m2!3d4.6216536!4d-74.1650013!16s%2Fg%2F1tdksvtw?entry=ttu&g_ep=EgoyMDI1MTEwOS4wIKXMDSoASAFQAw%3D%3D | P12: Pendiente confirmar con delegado
A13: SUR | B13: BOGOTA. D.C. - LOCALIDAD 8 KENNEDY | C13: Kennedy Central | D13: 11:00 AM | E13: ENSEÑANZA | F13: AFINIDAD | G13: Diciembre | H13: Domingo | I13: 46005 | J13: Reunion de Afinidad Objetivo Que los hnos puedan compartir con nuestros representantes, y ellos puedan motivarlos a activar sus referidos y a participar activamente del bingo Logística Invitar a los hnos para que al finalizar el culto suban, Enviaremos una invitación a los líderes que tienen menos de 5 referidos para que asistan Contaremos con sonido y cabina con micrófono En el televisor se proyectarán videos de la leyes del partido, para que mientras nuestros representantes suban puedan los asistentes verlos Activación de líderes, en info mira | L13: AV CR 80 NO 42C 83 SUR | M13: 4.622006495658455, -74.16497448186743 | N13: google.com/maps/place/Iglesia+de+Dios+Ministerial+de+Jesucristo+Internacional+-+IDMJI+-+CGMJI+BTA+EL+OLIVO/@4.6215758,-74.164928,3a,75y,316.8h,90t/data=!3m7!1e1!3m5!1sJwIftdN6Rl-LMLqtdi_3Nw!2e0!6shttps:%2F%2Fstreetviewpixels-pa.googleapis.com%2Fv1%2Fthumbnail%3Fcb_client%3Dmaps_sv.tactile%26w%3D900%26h%3D600%26pitch%3D0%26panoid%3DJwIftdN6Rl-LMLqtdi_3Nw%26yaw%3D316.80283!7i16384!8i8192!4m14!1m7!3m6!1s0x8e3f9e842a6a8335:0xe8f39c19a9ab6da3!2sIglesia+de+Dios+Ministerial+de+Jesucristo+Internacional+-+IDMJI+-+CGMJI+BTA+EL+OLIVO!8m2!3d4.6216536!4d-74.1650013!16s%2Fg%2F1tdksvtw!3m5!1s0x8e3f9e842a6a8335:0xe8f39c19a9ab6da3!8m2!3d4.6216536!4d-74.1650013!16s%2Fg%2F1tdksvtw?entry=ttu&g_ep=EgoyMDI1MTEwOS4wIKXMDSoASAFQAw%3D%3D | P13: Pendiente confirmar con delegado
A14: SUR | B14: BOGOTA. D.C. - LOCALIDAD 8 KENNEDY | C14: Kennedy Central | D14: 1:30 PM | E14: ALMUERZO | F14: N/A | G14: Diciembre | H14: Domingo | I14: 46005 | J14: En la sede | K14: N/A | O14: Kennedy | P14: Definir por congreso y Concejo nùmero de asistentes para confirmar a la lìder | Q14: Jenny García - Delegada Política 3108524285 | R14: Definir por congreso y Concejo nùmero de asistentes para confirmar a la lìder
A15: SUR | B15: BOGOTA. D.C. - LOCALIDAD 8 KENNEDY | C15: Kennedy Central | D15: 3:00 PM | E15: TERRITORIO | F15: POLITICO COMUNITARIA | G15: Diciembre | H15: Domingo | I15: 46005 | J15: MT - ROMA IV 1ER SECTOR MALLA VIAL (1969) Reunión con sector comercial y habitantes de Roma + MT - CASABLANCA JORNADA OPAM (5646) | K15: 1. En este sector se está gestionando arreglo de 3 segmentos viales, del cual 1 la Alcaldía ya està ejecutando su arreglo 2. Jornada Opam 3. Visita con Secretaría de Movilidad para abordar problemáticas de movilidad 4. Jornada de OPAM 5. Arreglo de paradero del SITP | L15: Calle 58C#78K21 Salón comunal rubí 2 | M15: https://maps.app.goo.gl/jzrd7SQfeCSpVLPRA | O15: Roma | P15: 40
A16: SUR | B16: BOGOTA. D.C. - LOCALIDAD 8 KENNEDY | C16: Kennedy Central | D16: 5.30 PM | E16: TERRITORIO | F16: POLITICO COMUNITARIA | G16: Diciembre | H16: Domingo | I16: 46005 | J16: MT - LAS MARGARITAS ZONAS DE CESION (4329) | K16: 1. Trabajo en entrega de zonas de cesión, se logrò un parque 2. Embellecimiento de parque 3. Jornada personalización del SITP | L16: Cra 89a No 46-45 sur | M16: 4.634426583502856, -74.17797154061991 | N16: https://www.google.com/maps/@4.6341727,-74.1779911,3a,75y,356.8h,87.57t/data=!3m7!1e1!3m5!1sMhvKblnUolqsI7uZqgsS9g!2e0!6shttps:%2F%2Fstreetviewpixels-pa.googleapis.com%2Fv1%2Fthumbnail%3Fcb_client%3Dmaps_sv.tactile%26w%3D900%26h%3D600%26pitch%3D2.4308615552782413%26panoid%3DMhvKblnUolqsI7uZqgsS9g%26yaw%3D356.7964580580785!7i16384!8i8192?entry=ttu&g_ep=EgoyMDI1MTEyMy4xIKXMDSoASAFQAw%3D%3D | O16: Las Margaritas | P16: 40 | Q16: Rafael Gutierrez (3114901573)
A17: SUR | B17: BOGOTA. D.C. - LOCALIDAD 8 KENNEDY | C17: Carvajal | D17: 7:00 AM | E17: ALABANZA | F17: AFINIDAD | G17: Diciembre | H17: Martes | I17: 46007 | J17: REUNION EN EL SEGUNDO PISO CON LIDERES QUE NO TIENEN REFERIDOS Y CON LOS QUE SOLO TIENEN 5 REFERIDOS | K17: 1. Saludo de los representantes 2..contar que se ha hecho en territorio y motivar a los lideres a activar sus referidos. 3. Explicacion de como votar, inscripciones de cedulas, presentacion de publicidad de candidatos | L17: Av. Boyacá #25 Sur NO 35 | M17: 4.616503452100983, -74.14045373278768 | N17: google.com/maps/place/Iglesia+De+Dios+Ministerial+De+Jesucristo+Internacional+-+IDMJI+-CARVAJAL/@4.6162521,-74.1430179,17z/data=!3m1!4b1!4m6!3m5!1s0x8e3f9ebb73ed00eb:0x84ff2c16af65e299!8m2!3d4.6162468!4d-74.140443!16s%2Fg%2F1ptwb97lz?entry=ttu&g_ep=EgoyMDI1MTEyMy4xIKXMDSoASAFQAw%3D%3D | O17: Carvajal | Q17: Sergio Osorio (Delagado Político) 3505621182
A18: SUR | B18: BOGOTA. D.C. - LOCALIDAD 8 KENNEDY | C18: Carvajal | D18: 10:00 AM | E18: TERRITORIO | F18: POLITICO COMUNITARIA | G18: Diciembre | H18: Martes | I18: 46007 | J18: MT - CARVAJAL PARE ACOSTADO MAL PARQUEO PARQUE MARACANA | K18: 1. Arreglo de pare 2, ARREGLO TAPA TELCOMUNCIACIONES 3, Arrglo de arreglo vanti en el Parque | L18: Cra 72 p #37b-10 sur carvajal | M18: https://maps.app.goo.gl/xS5efNYhdefHghuv9 | N18: 4.615524863281549, -74.1456626069883 | O18: Carvajal | P18: 20 | Q18: Carmen Garzón
A19: SUR | B19: BOGOTA. D.C. - LOCALIDAD 8 KENNEDY | C19: Carvajal | D19: 12:00 M | E19: ALMUERZO | F19: N/A | G19: Diciembre | H19: Martes | I19: 46007 | J19: Almuerzo
A20: SUR | B20: BOGOTA. D.C. - LOCALIDAD 8 KENNEDY | C20: Carvajal | D20: 2:00 PM | E20: TERRITORIO | F20: POLITICO COMUNITARIA | G20: Diciembre | H20: Martes | I20: 46007 | J20: MT - AMERICAS CLÍNICA OCCIDENTE MALLA VIAL (2052) | K20: 1. Arreglo de 2 hundimientos | L20: carrera 71a bis #5a25 | M20: https://maps.app.goo.gl/VxzbReTCnYvUc91L7 | N20: 4.628287390266298, -74.13407056035354 | O20: Americas Central | P20: 20 | Q20: Gloria Rincón
A21: SUR | B21: BOGOTA. D.C. - LOCALIDAD 8 KENNEDY | C21: Carvajal | D21: 4:00 PM | E21: TERRITORIO | F21: POLITICO COMUNITARIA | G21: Diciembre | H21: Martes | I21: 46007 | J21: MT - MANDALAY OBRAS DE RENOVACIÓN EAAB (3269) | K21: 1. Nivelaciòn de vìa tras arreglo de Acueducto | L21: Avenida De Las Américas # 73 – 67 | M21: https://maps.app.goo.gl/gc1LMZ72Lqdxi2nT6 | N21: 4.630632908010167, -74.14153391665295 | O21: Mandalay | P21: 20 | Q21: Jimmy Gutierrez
A22: SUR | B22: BOGOTA. D.C. - LOCALIDAD 8 KENNEDY | C22: Carvajal | D22: 6:00 PM | E22: ALABANZA | F22: AFINIDAD | G22: Diciembre | H22: Martes | I22: 46007 | J22: REUNION EN EL SEGUNDO PISO CON LIDERES QUE NO TIENEN REFERIDOS Y CON LOS QUE SOLO TIENEN 5 REFERIDOS | K22: 1. Saludo de los representantes 2..contar que se ha hecho en territorio y motivar a los lideres a activar sus referidos. 3. Explicacion de como votar, inscripciones de cedulas, presentacion de publicidad de candidatos | L22: Av. Boyacá #25 Sur NO 35 | M22: 4.616503452100983, -74.14045373278768 | N22: google.com/maps/place/Iglesia+De+Dios+Ministerial+De+Jesucristo+Internacional+-+IDMJI+-CARVAJAL/@4.6162521,-74.1430179,17z/data=!3m1!4b1!4m6!3m5!1s0x8e3f9ebb73ed00eb:0x84ff2c16af65e299!8m2!3d4.6162468!4d-74.140443!16s%2Fg%2F1ptwb97lz?entry=ttu&g_ep=EgoyMDI1MTEyMy4xIKXMDSoASAFQAw%3D%3D | O22: Carvajal | Q22: Sergio Osorio (Delagado Político) 3505621182
A23: SUR | B23: BOGOTA. D.C. - LOCALIDAD 8 KENNEDY | C23: Carvajal | D23: 8:00 PM | E23: TERRITORIO | F23: POLITICO COMUNITARIA | G23: Diciembre | H23: =TEXT(I23,"dddd") -> viernes | I23: 46010 | J23: Reunión con DP para seguimiento de preparativos de reuniones campaña enero | K23: Reunión con DP para seguimiento de preparativos de reuniones campaña enero | L23: Virtual | M23: Virtual | N23: Virtual | O23: Virtual | Q23: Fernando Zamora - Lorena Garzón
A24: SUR | B24: BOGOTA. D.C. - LOCALIDAD 8 KENNEDY | C24: Carvajal | D24: 8:00 am | E24: BINGO | F24: AFINIDAD | G24: Diciembre | H24: sábado | I24: 46011 | J24: Bingo | K24: Bingo | L24: Av. Boyacá #25 Sur NO 35 | M24: google.com/maps/place/Iglesia+De+Dios+Ministerial+De+Jesucristo+Internacional+-+IDMJI+-CARVAJAL/@4.6162521,-74.1430179,17z/data=!3m1!4b1!4m6!3m5!1s0x8e3f9ebb73ed00eb:0x84ff2c16af65e299!8m2!3d4.6162468!4d-74.140443!16s%2Fg%2F1ptwb97lz?entry=ttu&g_ep=EgoyMDI1MTEyMy4xIKXMDSoASAFQAw%3D%3D | N24: 4.616503452100983, -74.14045373278768 | O24: Carvajal | P24: 100 | Q24: Sergio Osorio (Delagado Político) 3505621182
A25: SUR | B25: BOGOTA. D.C. - LOCALIDAD 8 KENNEDY | C25: Kennedy Central | D25: 8:00 am | E25: BINGO | F25: AFINIDAD | G25: Diciembre | H25: sábado | I25: 46011 | J25: Bingo | K25: Bingo | L25: AV CR 80 NO 42C 83 SUR | M25: google.com/maps/place/Iglesia+de+Dios+Ministerial+de+Jesucristo+Internacional+-+IDMJI+-+CGMJI+BTA+EL+OLIVO/@4.6215758,-74.164928,3a,75y,316.8h,90t/data=!3m7!1e1!3m5!1sJwIftdN6Rl-LMLqtdi_3Nw!2e0!6shttps:%2F%2Fstreetviewpixels-pa.googleapis.com%2Fv1%2Fthumbnail%3Fcb_client%3Dmaps_sv.tactile%26w%3D900%26h%3D600%26pitch%3D0%26panoid%3DJwIftdN6Rl-LMLqtdi_3Nw%26yaw%3D316.80283!7i16384!8i8192!4m14!1m7!3m6!1s0x8e3f9e842a6a8335:0xe8f39c19a9ab6da3!2sIglesia+de+Dios+Ministerial+de+Jesucristo+Internacional+-+IDMJI+-+CGMJI+BTA+EL+OLIVO!8m2!3d4.6216536!4d-74.1650013!16s%2Fg%2F1tdksvtw!3m5!1s0x8e3f9e842a6a8335:0xe8f39c19a9ab6da3!8m2!3d4.6216536!4d-74.1650013!16s%2Fg%2F1tdksvtw?entry=ttu&g_ep=EgoyMDI1MTEwOS4wIKXMDSoASAFQAw%3D%3D | N25: 4.622006495658455, -74.16497448186743 | O25: Kennedy Central | P25: 100 | Q25: Jenny García (3108524285)
A26: SUR | B26: BOGOTA. D.C. - LOCALIDAD 8 KENNEDY | C26: Class | D26: 7:00 AM | E26: ALABANZA | F26: AFINIDAD | G26: Diciembre | H26: Martes | I26: 46014 | J26: Reunion Identidad y Conviccion y motivacion a personas recientes en la iglesia | K26: Afinidad | L26: Cra. 80a #56-51 | M26: https://www.google.com/maps/place/IDMJI+Class+Roma/@4.6141834,-74.1760423,3a,75y,329.85h,84.86t/data=!3m7!1e1!3m5!1s_5pKrbVhz2n3AEOMoun0Lg!2e0!6shttps:%2F%2Fstreetviewpixels-pa.googleapis.com%2Fv1%2Fthumbnail%3Fcb_client%3Dmaps_sv.tactile%26w%3D900%26h%3D600%26pitch%3D5.144541014976355%26panoid%3D_5pKrbVhz2n3AEOMoun0Lg%26yaw%3D329.8452991252842!7i16384!8i8192!4m14!1m7!3m6!1s0x8e3f9f3434c2710b:0x65030ca5b65a340e!2sIDMJI+Class+Roma!8m2!3d4.6142421!4d-74.1762168!16s%2Fg%2F11fq5t0q39!3m5!1s0x8e3f9f3434c2710b:0x65030ca5b65a340e!8m2!3d4.6142421!4d-74.1762168!16s%2Fg%2F11fq5t0q39?entry=ttu&g_ep=EgoyMDI1MTEyMy4xIKXMDSoASAFQAw%3D%3D | N26: 4.614423894411722, -74.17613097327387 | O26: Class | P26: Pendiente confirmar con delegado | Q26: Bryan Rodríguez (3202378579)
A27: SUR | B27: BOGOTA. D.C. - LOCALIDAD 8 KENNEDY | C27: Class | D27: 6:30 PM | E27: ALABANZA | F27: AFINIDAD | G27: Diciembre | H27: Martes | I27: 46014 | J27: Micro reunion con líderes que tienen de 0 a 5 referidos; objetivo motivarlos a hablar del partido | K27: Afinidad | L27: Cra. 80a #56-51 | M27: https://www.google.com/maps/place/IDMJI+Class+Roma/@4.6141834,-74.1760423,3a,75y,329.85h,84.86t/data=!3m7!1e1!3m5!1s_5pKrbVhz2n3AEOMoun0Lg!2e0!6shttps:%2F%2Fstreetviewpixels-pa.googleapis.com%2Fv1%2Fthumbnail%3Fcb_client%3Dmaps_sv.tactile%26w%3D900%26h%3D600%26pitch%3D5.144541014976355%26panoid%3D_5pKrbVhz2n3AEOMoun0Lg%26yaw%3D329.8452991252842!7i16384!8i8192!4m14!1m7!3m6!1s0x8e3f9f3434c2710b:0x65030ca5b65a340e!2sIDMJI+Class+Roma!8m2!3d4.6142421!4d-74.1762168!16s%2Fg%2F11fq5t0q39!3m5!1s0x8e3f9f3434c2710b:0x65030ca5b65a340e!8m2!3d4.6142421!4d-74.1762168!16s%2Fg%2F11fq5t0q39?entry=ttu&g_ep=EgoyMDI1MTEyMy4xIKXMDSoASAFQAw%3D%3D | N27: 4.614423894411722, -74.17613097327387 | O27: Class | P27: Pendiente confirmar con delegado | Q27: Albeiro Rodriguez (3124215077)
A28: SUR | B28: BOGOTA. D.C. - LOCALIDAD 8 KENNEDY | C28: Kennedy Central | D28: 8:00 AM | E28: ENSEÑANZA | F28: AFINIDAD | G28: Diciembre | H28: Domingo | I28: 46019 | J28: Actividad de afinidad - activación de líderes y referidos [PENDIENTE DELEGADO DESCRIBIR LA ACTIVIDAD] | K28: Afinidad | L28: AV CR 80 NO 42C 83 SUR | M28: https://maps.app.goo.gl/B7Vvnj17Ra5gpNUL9 | N28: 4.622006495658455, -74.16497448186743 | O28: Kennedy Central | P28: Pendiente confirmar con delegado | Q28: Jenny García (3108524285)
A29: SUR | B29: BOGOTA. D.C. - LOCALIDAD 8 KENNEDY | C29: Kennedy Central | D29: 11:00 AM | E29: ENSEÑANZA | F29: AFINIDAD | G29: Diciembre | H29: Domingo | I29: 46019 | J29: Actividad de afinidad - activación de líderes y referidos [PENDIENTE DELEGADO DESCRIBIR LA ACTIVIDAD] | K29: Afinidad | L29: AV CR 80 NO 42C 83 SUR | M29: https://maps.app.goo.gl/B7Vvnj17Ra5gpNUL9 | N29: 4.622006495658455, -74.16497448186743 | O29: Kennedy Central | P29: Pendiente confirmar con delegado | Q29: Jenny García (3108524285)
A30: SUR | B30: BOGOTA. D.C. - LOCALIDAD 8 KENNEDY | C30: Patio Bonito | D30: 7:00 AM | E30: ALABANZA | F30: AFINIDAD | G30: Enero | H30: Viernes | I30: 46024 | J30: Actividad de afinidad - activación de líderes y referidos [PENDIENTE DELEGADO DESCRIBIR LA ACTIVIDAD] | K30: Afinidad | L30: Cra 95A #39 SUR NO.38C | M30: https://maps.app.goo.gl/aGBx2P51EGsbTbt19 | N30: 4.646227879789345, -74.17302253463195 | O30: Patio Bonito | P30: Pendiente confirmar con delegado | Q30: Hamilton Liz (3125621911)
A31: SUR | B31: BOGOTA. D.C. - LOCALIDAD 8 KENNEDY | C31: Patio Bonito | D31: 6:00 PM | E31: ALABANZA | F31: AFINIDAD | G31: Enero | H31: Viernes | I31: 46024 | J31: Actividad de afinidad - activación de líderes y referidos [PENDIENTE DELEGADO DESCRIBIR LA ACTIVIDAD] | K31: Afinidad | L31: Cra 95A #39 SUR NO.38C | M31: https://maps.app.goo.gl/aGBx2P51EGsbTbt19 | N31: 4.646227879789345, -74.17302253463195 | O31: Patio Bonito | P31: Pendiente confirmar con delegado | Q31: Hamilton Liz (3125621911)
A32: SUR | B32: BOGOTA. D.C. - LOCALIDAD 8 KENNEDY | C32: Class | D32: 7:00 AM | E32: ALABANZA | F32: AFINIDAD | G32: Enero | H32: Martes | I32: 46035 | J32: Actividad de afinidad - activación de líderes y referidos Colaboradores de la iglesia | K32: Afinidad | L32: KR 80A # 56 35 SUR CLASS ROMA | M32: https://www.google.com/maps?q=4.614135243,-74.17617048 | N32: 4.614295606307947, -74.17625633511189 | O32: CLASS ROMA | Q32: N/A
A33: SUR | B33: BOGOTA. D.C. - LOCALIDAD 8 KENNEDY | C33: Class | D33: 11:00 AM | E33: TERRITORIO | F33: POLITICO COMUNITARIA | G33: Enero | H33: Martes | I33: 46035 | J33: MT – PORTAL DE CALI REDES DE ACUEDUCTO (2015) | K33: 1. Limpieza de sumideros y de caja por medio del vactor 2. Limpieza de punto critico de basura | L33: CARRERA 82B#54B 11SUR CASA 91 | M33: https://maps.app.goo.gl/L7WTUHHDCAwqR5Z87 | N33: 4.620655888758921, -74.17926693629067 | O33: Portal de Cali | P33: 25 | Q33: Blanca
A34: SUR | B34: BOGOTA. D.C. - LOCALIDAD 8 KENNEDY | C34: Class | D34: 12:30 M | E34: ALMUERZO | F34: N/A | G34: Enero | H34: Martes | I34: 46035 | J34: ALMUERZO | K34: ALMUERZO
A35: SUR | B35: BOGOTA. D.C. - LOCALIDAD 8 KENNEDY | C35: Class | D35: 3:00 PM | E35: TERRITORIO | F35: POLITICO COMUNITARIA | G35: Enero | H35: Martes | I35: 46035 | J35: MT - VEGAS DE SANTA ANA MALLA VIAL E INUNDACIONES RÍO TUNJUELO (5509) | K35: 1. Jornada de personalización de Tu Llave 2. Mesa de trabajo con el Acueducto por afectaciones en las redes de alcantarillado | L35: Diagonal 57 A bis # 81 C - 27 sur | M35: https://maps.app.goo.gl/C5huNCbBnyA9KYG67 | N35: 4.616694700593081, -74.17972714463525 | O35: Vegas de Santa Ana | P35: 25 | Q35: Aldemar Rodriguez
A36: SUR | B36: BOGOTA. D.C. - LOCALIDAD 8 KENNEDY | C36: Class | D36: 4:30 PM | E36: TERRITORIO | F36: POLITICO COMUNITARIA | G36: Enero | H36: Martes | I36: 46035 | J36: Reunión con vecinos y familiares | K36: Rendición de cuentas | L36: Diagonal 56B sur #81J - 72 | M36: https://maps.app.goo.gl/KnubUPfDcHNqzmx5A | N36: 4.618603925849968, -74.18148190073752 | O36: Salem Samaria | P36: 20 | Q36: Liliana Malagon
A37: SUR | B37: BOGOTA. D.C. - LOCALIDAD 8 KENNEDY | C37: Class | D37: 6:30 PM | E37: ALABANZA | F37: AFINIDAD | G37: Enero | H37: Martes | I37: 46035 | J37: Actividad de afinidad - activación de líderes y referidos - Colaboradores de la iglesia | K37: Afinidad | L37: KR 80A # 56 35 SUR CLASS ROMA | M37: https://www.google.com/maps?q=4.614135243,-74.17617048 | N37: 4.614295606307947, -74.17625633511189 | O37: CLASS ROMA | Q37: N/A
C38: Patio Bonito | D38: 7:00 AM | E38: ENSEÑANZA | F38: AFINIDAD | G38: Enero | H38: Miércoles | I38: 46036 | K38: Afinidad | L38: Cra 95A #39 SUR NO.38C | M38: 4.646227879789345, -74.17302253463195 | N38: https://maps.app.goo.gl/aGBx2P51EGsbTbt19 | O38: Patio Bonito | Q38: Hamilton Liz (3125621911)
A39: SUR | B39: BOGOTA. D.C. - LOCALIDAD 8 KENNEDY | C39: Patio Bonito | D39: 2:00 PM | E39: TERRITORIO | F39: POLITICO COMUNITARIA | G39: Enero | H39: Miércoles | I39: 46036 | J39: VISITA MICROEMPRESA | K39: 1. Ley de micronegocios 2. Gestión en solicitudes puntuales de vecinos | L39: Cl. 33 Sur #89d-53 | M39: https://www.google.com/maps/@4.643407,-74.165419,3a,75y,276.93h,87.2t/data=!3m7!1e1!3m5!1s_zx3abQgk9whm3wZQIl9RA!2e0!6shttps:%2F%2Fstreetviewpixels-pa.googleapis.com%2Fv1%2Fthumbnail%3Fcb_client%3Dmaps_sv.tactile%26w%3D900%26h%3D600%26pitch%3D2.8031195662346704%26panoid%3D_zx3abQgk9whm3wZQIl9RA%26yaw%3D276.92928112065755!7i16384!8i8192?entry=ttu&g_ep=EgoyMDI2MDEwNy4wIKXMDSoASAFQAw%3D%3D | N39: 4.643631506000829, -74.16557307731713 | O39: Unir 1 | P39: 15 | Q39: ALVARO GARZÓN
A40: SUR | B40: BOGOTA. D.C. - LOCALIDAD 8 KENNEDY | C40: Patio Bonito | D40: 4:00 PM | E40: TERRITORIO | F40: POLITICO COMUNITARIA | G40: Enero | H40: Miércoles | I40: 46036 | J40: Riveras de Occidente | K40: 1. Gestión de arreglo de vía | L40: Cra. 93b # 26 Sur - 1 | M40: https://www.google.com/maps/@4.6473158,-74.1676827,3a,75y,215.87h,79.72t/data=!3m7!1e1!3m5!1sL-INdquaOGG3IsrmzWzolw!2e0!6shttps:%2F%2Fstreetviewpixels-pa.googleapis.com%2Fv1%2Fthumbnail%3Fcb_client%3Dmaps_sv.tactile%26w%3D900%26h%3D600%26pitch%3D10.282519976709054%26panoid%3DL-INdquaOGG3IsrmzWzolw%26yaw%3D215.86822430098266!7i16384!8i8192?entry=ttu&g_ep=EgoyMDI1MTIwOS4wIKXMDSoASAFQAw%3D%3D | N40: 4.647150036969973, -74.16782757241296 | O40: Riveras de Occidente | P40: 40 | Q40: VERONICA AVILA
...

Sheet Hoja 28
A1: AÑO | B1: COD MES | C1: MES INICIO | D1: CÓDIGO SEGUIMIENTO | E1: TIPO DE ACTIVIDAD | F1: TEMA | G1: SUBTEMA | H1: DESCRIPCIÓN Y/O ACTIVIDAD | I1: ENTIDADES | J1: BARRIO | K1: ZONA | L1: LOCALIDAD | M1: IGLESIA | N1: COORDENADAS - IGLESIA | O1: TIPO DE GESTIÓN | P1: NOMBRE DEL BENEFICIARIO Y/O LÍDER | Q1: GÉNERO | R1: CÉDULA | S1: DIRECCIÓN DEL BARRIO | T1: COORDENADAS DE LA REUNIÓN/ GESTIÓN | U1: CORREO | V1: TELEFONO | W1: PRIORIZACIÓN | X1: BENEFICIADO | Y1: ESTADO ACTUAL DEL TRÁMITE | Z1: RESULTADOS DE LA GESTIÓN | AA1: OBSERVACIONES | AB1: FECHA DE INICIO | AC1: FECHA DE CIERRE | AD1: ENCARGADO | AE1: NOMBRE DEL ASESOR ENCARGADO| | AF1: CIUDAD | AG1: DEPARTAMENTO | AH1: LINK DE EVIDENCIA | AI1: SEMANA | AJ1: CONTACTADO POR AFINIDAD
A2: 2024 | B2: 1 | C2: Enero | D2: 202400007 | E2: Apoyo Ciudadano | F2: Salud | G2: Citas médicas | H2: Requerimiento cita neumología pediátrica Datos clínicos de importancia Asma infantil crónica. | I2: Secretaría Distrital de Salud | J2: Castilla | K2: Sur | L2: 08.Kennedy | M2: N/A | N2: =BUSCARX(R[0]C[-1],CONVENCIONES!R12C1:R42C1,CONVENCIONES!R12C2:R42C2) -> #ERROR! | O2: Gestión 2024 | P2: Lian Samuel Victoria Sánchez | Q2: Hombre | R2: 1145933937 | S2: Calle 10b # 81f-92 | T2: 4.650055904649422, -74.14550204826222 | U2: jaime.victoria2671@correo.policia.gov.co | V2: 3143946191 | W2: Tramites | X2: Interno | Y2: Finalizado | Z2: Positivo | AA2: N/A | AB2: 45314 | AC2: N/A | AD2: Asesor | AE2: Angie Benitez | AF2: Bogotá | AG2: Cundinamarca | AH2: 202400007_Lian Samuel Victoria Sánchez | AJ2: NO
A3: 2024 | B3: 1 | C3: Enero | D3: 202400025 | E3: Apoyo Ciudadano | F3: Educación | H3: Cupo estudiantil a menor migrante venezolana | I3: Secretaría de Educación del Distrito | J3: Andalucia 1er sector | K3: Sur | L3: 08.Kennedy | M3: N/A | N3: =BUSCARX(R[0]C[-1],CONVENCIONES!R12C1:R42C1,CONVENCIONES!R12C2:R42C2) -> #ERROR! | O3: Gestión 2024 | P3: Nombres del estudiante: Daniela Stefani Guzamana Mendez Pasaporte: 172513001 Correo: tovaryuliath@gmail.com Grado: Décimo Acudiente Nombres: Yuliath Celiana Tovar Guzamana PPT: 7109640 Correo: tovaryuliath@gmail.com Contacto: 3213646592 Líder que hizo la solicitud: Antonio Castaño Celular: 3178294782 | Q3: Mujer | R3: 7109640 | S3: N/A | T3: 4.65544903829502, -74.13812385348416 | U3: tovaryuliath@gmail.com Correo: tovaryuliath@gmail.com | V3: Contacto: 3213646592 | W3: Tramites | X3: Externos | Y3: Finalizado | Z3: Positivo | AA3: N/A | AB3: 41668 | AC3: N/A | AD3: Asesor | AE3: Angie Benitez | AF3: Bogotá | AG3: Cundinamarca | AH3: 202400025_Yuliath Celiana Tovar Guzamana | AJ3: NO
A4: 2024 | B4: 2 | C4: Febrero | D4: 202400038 | E4: Apoyo Ciudadano | F4: Educación | G4: cupo escolar | H4: Maritza Lopez Castañeda, solicita ayuda con un cupo Estudiantil | I4: Secretaría de Educación del Distrito | J4: Kennedy | K4: Sur | L4: 08.Kennedy | M4: 08.Kennedy Central | N4: =BUSCARX(R[0]C[-1],CONVENCIONES!R12C1:R42C1,CONVENCIONES!R12C2:R42C2) -> #ERROR! | O4: Gestión 2024 | P4: Maritza Lopez Castañeda | Q4: Mujer | R4: 1028785887 | S4: N/A | T4: N/A | U4: maritzalopez2808@gmail.com | V4: 3226438335 | W4: Tramites | X4: Interno | Y4: Finalizado | Z4: Positivo | AA4: El enlace nos colabora con el cupo escolar en el colegio jornada tarde, pero la acudiente no acepto y prefirió continuar en el mismo colegio. | AB4: 45330 | AC4: 44966 | AD4: Asesor | AE4: Katherine Galindo | AF4: Bogotá | AG4: Cundinamarca | AH4: Maritza López Castañeda | AJ4: NO
A5: 2024 | B5: 2 | C5: Febrero | D5: 202400079 | E5: Apoyo Ciudadano | F5: Salud | G5: Procedimientos y exámenes | H5: Solicitud: verificación diagnóstico y tratamiento a realizar ya que el primer concepto indican que no le harán tratamiento Diagnóstico: cáncer de hígado (no conocen que tipo de cáncer, solo hicieron una biopsia y no pudieron identificar el cáncer). Tiempo de solicitud: lleva 2 meses en la clínica sin respuesta | I5: Superintendencia de Salud | J5: Roma | K5: Sur | L5: 08.Kennedy | M5: 08.Class | N5: =BUSCARX(R[0]C[-1],CONVENCIONES!R12C1:R42C1,CONVENCIONES!R12C2:R42C2) -> #ERROR! | O5: Gestión 2024 | P5: Gerardo Ávila | Q5: Hombre | R5: 4894006 | S5: calle 56a sur # 78 N 48 manzana 44 interior 1 apto 101 | T5: 4.6131323776124855, -74.17500280572317 | U5: N/A | V5: Falleció la persona. | W5: Tramites | X5: Interno | Y5: Finalizado | Z5: N/A | AA5: Falleció la persona. | AB5: 45351 | AC5: N/A | AD5: Asesor | AE5: Angie Benitez | AF5: Bogotá | AG5: Cundinamarca | AH5: 202400079_Gerardo Ávila | AJ5: NO
A6: 2024 | B6: 3 | C6: Marzo | D6: 202400082 | E6: Apoyo Ciudadano | F6: Salud | H6: La familia de un adulto mayor con discapacidad solicita apoyo ya que se encuentra delicado de salud y solicitan ayuda para ingresarlo en un geratrico donde lo puedan cuidar. | I6: Secretaría Distrital de Integración Social | J6: Patio Bonito | K6: Sur | L6: 08.Kennedy | M6: 08.Patio Bonito | N6: =BUSCARX(R[0]C[-1],CONVENCIONES!R12C1:R42C1,CONVENCIONES!R12C2:R42C2) -> #ERROR! | O6: Gestión 2024 | P6: Gildardo Ayala | Q6: Hombre | R6: 5947933 | S6: N/A | T6: 4.638160202192498, -74.16295192449837 | U6: N/A | V6: 3104781799 | W6: Tramites | X6: Interno | Y6: Finalizado | Z6: Negativo | AA6: No se le puede brindar algún tipo de apoyo ya que la persona no se encuentra en Bogotá | AB6: 45352 | AC6: =DIA.LAB(R[0]C[-1],15) -> #ERROR! | AD6: Asesor | AE6: Fernando Zamora | AF6: Bogotá | AG6: Cundinamarca | AH6: 202400082_Gildardo Ayala | AJ6: NO
A7: 2024 | B7: 3 | C7: Marzo | D7: 202400086 | E7: Apoyo Ciudadano | F7: Salud | H7: La Sra Yolanda Garzón solicita cita con especialista en oftamología por primera vez, lleva mas de 6 meses esperando la cita y esta perdiendo la vista | I7: Secretaría Distrital de Salud | J7: Tierra Buena | K7: Sur | L7: 08.Kennedy | M7: 08.Patio Bonito | N7: =BUSCARX(R[0]C[-1],CONVENCIONES!R12C1:R42C1,CONVENCIONES!R12C2:R42C2) -> #ERROR! | O7: Gestión 2024 | P7: Yolanda Garzón | Q7: Mujer | R7: 41308189 | S7: calle 26 sur #95a49 | T7: 4.650076195336499, -74.16991540572303 | U7: N/A | V7: 3228569868 | W7: Tramites | X7: Interno | Y7: Finalizado | Z7: Positivo | AA7: Se programa la cita correspondiente | AB7: 45362 | AC7: =DIA.LAB(R[0]C[-1],15) -> #ERROR! | AD7: Asesor | AE7: Fernando Zamora | AF7: Bogotá | AG7: Cundinamarca | AH7: 202400086_Yolanda Garzón | AJ7: NO
A8: 2024 | B8: 3 | C8: Marzo | D8: 202400090 | E8: Apoyo Ciudadano | F8: Salud | G8: Citas médicas | H8: Diagnóstico: tuvo un accidente practicando el deporte de clavados en natación. Solicitudes: * Cita: Resonancia de Orbitas, esta cita está agendado para el 6 de abril, pero se necesita urgente o anticiparla porque sus ojos están afectados por el accidente. * Cita: Neurocirugía 1a vez, para esta cita dicen que no hay agenda. | I8: Secretaría Distrital de Salud | J8: Ciudad de cali - patio bonito | K8: Sur | L8: 08.Kennedy | M8: 08.Kennedy Central | N8: =BUSCARX(R[0]C[-1],CONVENCIONES!R12C1:R42C1,CONVENCIONES!R12C2:R42C2) -> #ERROR! | O8: Gestión 2024 | P8: Nombre de la menor: Viviana Marulanda Valenzuela. Datos de la acudiente: Emilse Valenzuela - celular: 312 4310711 | Q8: Mujer | R8: 1.141.327.972 | S8: Carrera 86c bis No 42-51 sur | T8: 4.632030395354502, -74.16841293455875 | U8: emilce095@gmail.com | V8: 312 4310711 | W8: Tramites | X8: Interno | Y8: Finalizado | Z8: Positivo | AA8: N/A | AB8: 45363 | AC8: 45365 | AD8: Asesor | AE8: Angie Benitez | AF8: Bogotá | AG8: Cundinamarca | AH8: 202400090_Emilse Valenzuela | AJ8: NO
A9: 2024 | B9: 3 | C9: Marzo | D9: 202400091 | E9: Apoyo Ciudadano | F9: Salud | G9: Citas médicas | H9: Diagnóstico: hiperplasia de próstata Control por especialista en Urologia | I9: Secretaría Distrital de Salud | J9: Las margaritas | K9: Sur | L9: 08.Kennedy | M9: 08.Kennedy Central | N9: =BUSCARX(R[0]C[-1],CONVENCIONES!R12C1:R42C1,CONVENCIONES!R12C2:R42C2) -> #ERROR! | O9: Gestión 2024 | P9: Raúl Hernández | Q9: Hombre | R9: 19.437.301 | S9: Calle 46 sur # 86-41 Casa 384 alamedas de san José 2 zona las margaritas localidad de Kennedy | T9: 4.628496889205801, -74.17446470572308 | U9: dianis6413@gmail.com | V9: 3143367599 | W9: Tramites | X9: Interno | Y9: Finalizado | Z9: Positivo | AA9: N/A | AB9: 45364 | AC9: 45370 | AD9: Asesor | AE9: Angie Benitez | AF9: Bogotá | AG9: Cundinamarca | AH9: 202400091_Raúl Hernández | AJ9: NO
A10: 2024 | B10: 3 | C10: Marzo | D10: 202400093 | E10: Apoyo Ciudadano | F10: Salud | G10: Entrega de equipos médicos | H10: Diagnóstico: Trombosis en pierna. Solicitud: silla de ruedas. contexto: fueron presencialmente que ya no hay ese servicio. la justificación fue una resolución. | I10: Secretaría Distrital de Salud | J10: Las margaritas | K10: Sur | L10: 08.Kennedy | M10: 08.Kennedy Central | N10: =BUSCARX(R[0]C[-1],CONVENCIONES!R12C1:R42C1,CONVENCIONES!R12C2:R42C2) -> #ERROR! | O10: Gestión 2024 | P10: José Antonio Mendoza Vera | Q10: Hombre | R10: 2278975 | S10: Dirección :carrera 89 a 45a 38 sur Barrio : margaritas etapa 1, torre 23, apto 201 | T10: 4.634271482873386, -74.17697183455873 | U10: albam6075@gmail.com | V10: celular: 3114688767 - hija | W10: Tramites | X10: Interno | Y10: Pendiente | Z10: Negativo | AA10: No llamaron a la persona ni le hicieron la gestión. La persona ya está recuperada y no requiere el servicio. | AB10: 45365 | AC10: N/A | AD10: Asesor | AE10: Angie Benitez | AF10: Bogotá | AG10: Cundinamarca | AH10: 202400093_José Antonio Mendoza Vera | AJ10: NO
A11: 2024 | B11: 3 | C11: Marzo | D11: 202400104 | E11: Apoyo Ciudadano | F11: Salud | G11: Programación de cirugías | H11: Descripción del caso: Desde el mes de junio del año 2023 he venido presentando dolor severo continuo en parte abdominal y espalda baja del lado izquierdo por lo que me han visto doctores y ginecólogos, enviándome diferentes exámenes (ecografías transvaginales, antígeno carcinoembrionario, antígeno de cáncer de ovario, pruebas de embarazo exámenes de orina, exámenes de sangre en general) después de múltiples citas y al ver que los medicamentos no han dado ningún resultado, la ginecóloga Adriana Farias me dio orden de cirugía ( CISTECTOMIA DE OVARIO POR LAPAROSCOPIA) el día 06 de febrero de 2024, realice la autorización y me dieron el código asignado pero a la fecha no ha subido al sistema y debo seguir esperando a que me llamen para asignarme la clínica y la fecha de cirugía, yo sigo con dolores severos por lo que he acudido de urgencias a la clínica Colombia y al Hospital mayor Medery, verificando en nuevas ecografías que además del quiste en ovario izquierdo tengo endometriosis severa pero me dicen que no es una urgencia vital y por tanto no me pueden operar de urgencias, mi estado de salud es deplorable y mi calidad de vida va en descenso día a día al punto de tener que mandarme inyectar medicamentos fuertes como tramadol y dipirona, agradezco de corazón, la colaboración que me puedan brindar para agilizar mi cirugía de ovario izquierdo. | I11: Secretaría Distrital de Salud | J11: Castilla | K11: Sur | L11: 08.Kennedy | M11: N/A | N11: =BUSCARX(R[0]C[-1],CONVENCIONES!R12C1:R42C1,CONVENCIONES!R12C2:R42C2) -> #ERROR! | O11: Gestión 2024 | P11: Gina Lorena Lopez Mantilla | Q11: Mujer | R11: 52903620 | S11: Calle 8C 80 – 38 int 3 apto 512 conjunto Bosques de Bavaria Barrio Castilla | T11: 4.642836139522496, -74.14436504859762 | U11: glorenalopez@hotmail.com | V11: 301 5813744 | W11: Tramites | X11: Externos | Y11: Finalizado | Z11: Positivo | AA11: N/A | AB11: 45371 | AC11: N/A | AD11: Asesor | AE11: Angie Benitez | AF11: Bogotá | AG11: Cundinamarca | AH11: 202400104_Gina Lorena Lopez Mantilla | AJ11: NO
A12: 2024 | B12: 4 | C12: Abril | D12: 202400110 | E12: Apoyo Ciudadano | F12: Salud | G12: Citas médicas | H12: “Reciba un cordial saludo concejal, mi nombre es Martha Elizabeth Barbosa Sastoque y me encuentro en el régimen subsidiado a través de capital salud, desde el 23 de agosto del año 2023 llevo solicitando cita para optometría y me dieron el código de 890207. Asimismo, desde el 14 de agosto de 2023 estoy solicitando cita de otorrinolaringología a través del código 890282. Le agradecería si me ayudan a gestionar estas dos citas ya que llevo hace varios meses tratando de solicitarlas”. | I12: Secretaría Distrital de Salud | J12: Los periodistas | K12: Sur | L12: 08.Kennedy | M12: 08.Class | N12: =BUSCARX(R[0]C[-1],CONVENCIONES!R12C1:R42C1,CONVENCIONES!R12C2:R42C2) -> #ERROR! | O12: Gestión 2024 | P12: Martha Elizabeth Barbosa Sastoque | Q12: Mujer | R12: 52016841 | S12: Trav 78 h bis N 41-86 sur | T12: 4.616787189394192, -74.15697963455875 | U12: marelizbar1970@gmail.com | V12: 3024382399 | W12: Tramites | Y12: Finalizado | Z12: Positivo | AA12: N/A | AB12: 45384 | AC12: 45391 | AD12: Asesor | AE12: Angie Benitez | AF12: Bogotá | AG12: Cundinamarca | AH12: PENDIENTE LINK | AJ12: NO
A13: 2024 | B13: 4 | C13: Abril | D13: 202400140 | E13: Apoyo Ciudadano | F13: Salud | G13: Procedimientos y exámenes | H13: Diagnóstico: tumor benigno del tejido conjuntivo del abdomen. Solicitud: Biopsia cerrada intraabdominal. Tiempo de solicitud: Me han dilatado la solicitud más de un mes y nada que me hacen la biopsia, me remiten un lugar a otro y no me practican el procedimiento que me ordenó el médico. | I13: Secretaría Distrital de Salud | J13: El amparo | K13: Sur | L13: 08.Kennedy | M13: 08.Kennedy Central | N13: =BUSCARX(R[0]C[-1],CONVENCIONES!R12C1:R42C1,CONVENCIONES!R12C2:R42C2) -> #ERROR! | O13: Gestión 2024 | P13: Flower Alegrías Carbonero | Q13: N/A | R13: 76231536 | S13: calle 42#80g02 | T13: 4.6243384512631875, -74.16436231524406 | U13: floweralegrias979@gmail.com | V13: 311 5010594 | W13: Tramites | X13: Interno | Y13: Finalizado | Z13: Positivo | AA13: N/A | AB13: 45402 | AC13: 45412 | AD13: Asesor | AE13: Angie Benitez | AF13: Bogotá | AG13: Cundinamarca | AH13: PENDIENTE LINK | AJ13: NO
A14: 2024 | B14: 4 | C14: Abril | D14: 202400142 | E14: Apoyo Ciudadano | F14: Salud | G14: Citas médicas | H14: Diagnóstico: EPOC crónico, hipertensa, pasada un poco de peso. La señora depende del oxígeno las 24 horas debido a su avanzada edad, también se le dificulta caminar. Solicitud: cita pendiente con especialista en psiquiatria y solicitud de pañales talla XL. | I14: Secretaría Distrital de Salud | J14: Alcalá | K14: Sur | L14: 08.Kennedy | M14: 08.Kennedy Central | N14: =BUSCARX(R[0]C[-1],CONVENCIONES!R12C1:R42C1,CONVENCIONES!R12C2:R42C2) -> #ERROR! | O14: Gestión 2024 | P14: Rosa Matilde Sastoque de Barbosa. | Q14: Mujer | R14: 20925201 | S14: calle 30 sur #52-55 | T14: 4.604939983787324, -74.1276540345588 | U14: familiabarbosa321f@gmail.com | V14: 302 4382399 | W14: Tramites | Y14: Finalizado | Z14: Positivo | AA14: N/A | AB14: 45404 | AC14: N/A | AD14: Asesor | AE14: Angie Benitez | AF14: Bogotá | AG14: Cundinamarca | AH14: PENDIENTE LINK | AJ14: NO
A15: 2024 | B15: 4 | C15: Abril | D15: 202400144 | E15: Apoyo Ciudadano | F15: Salud | G15: Citas médicas | H15: Diagnóstico:secuelas de un acidente Solicitud: una consulta con especialista otorrinolaringología y otra con especialista en neurología Tiempo de solicitud:casi un año | I15: Secretaría Distrital de Salud | J15: Vegas de santa ana | K15: Sur | L15: 08.Kennedy | M15: N/A | N15: =BUSCARX(R[0]C[-1],CONVENCIONES!R12C1:R42C1,CONVENCIONES!R12C2:R42C2) -> #ERROR! | O15: Gestión 2024 | P15: Familiar: Yudit Rojas Paciente: Jhon Javier Gomez Sanchez | Q15: Hombre | R15: 1930645800 | S15: cra 81 j 57A- 95 sur | T15: 4.618483796471932, -74.18145065077307 | U15: Gómezjaver200@gmail.com | V15: 3217458382 | W15: Tramites | Y15: Finalizado | Z15: Pendiente | AA15: N/A | AB15: 45404 | AC15: N/A | AD15: Asesor | AE15: Angie Benitez | AF15: Bogotá | AG15: Cundinamarca | AH15: PENDIENTE LINK | AJ15: NO
A16: 2024 | B16: 4 | C16: Abril | D16: 202400149 | E16: Apoyo Ciudadano | F16: Salud | H16: Solicita una terapia | I16: Secretaría Distrital de Salud | J16: Tintal | K16: Sur | L16: 08.Kennedy | M16: 08.Kennedy Central | N16: =BUSCARX(R[0]C[-1],CONVENCIONES!R12C1:R42C1,CONVENCIONES!R12C2:R42C2) -> #ERROR! | O16: Gestión 2024 | P16: María Luzmila Rodríguez | Q16: Mujer | R16: 41445987 | S16: Calle 6a 88 51 Fase 2 | T16: 4.645569756879411, -74.15779493455871 | U16: N/A | V16: 3222262371 | W16: Tramites | X16: Interno | Y16: Finalizado | Z16: Positivo | AA16: Se programa la cita correspondiente | AB16: 45405 | AC16: =DIA.LAB(R[0]C[-1],15) -> #ERROR! | AD16: Asesor | AE16: Fernando Zamora | AF16: Bogotá | AG16: Cundinamarca | AH16: 202400149_María Luzmila Rodríguez | AJ16: NO
A17: 2024 | B17: 4 | C17: Abril | D17: 202400150 | E17: Apoyo Ciudadano | F17: Cementerios | H17: Solicitud de registro de defunsión que tiene reserva | I17: Registraduría | J17: Boita | K17: Sur | L17: 08.Kennedy | M17: 08.Kennedy Central | N17: =BUSCARX(R[0]C[-1],CONVENCIONES!R12C1:R42C1,CONVENCIONES!R12C2:R42C2) -> #ERROR! | O17: Gestión 2024 | P17: Diana Jaraba | Q17: Mujer | R17: 1007095114 | S17: calle 42 f sur #72h 95 | T17: 4.604087866462173, -74.14844373455881 | U17: jarababogada@gmail.com | V17: 301 6455867 | W17: Tramites | Y17: Finalizado | Z17: Positivo | AA17: N/A | AB17: 45405 | AC17: N/A | AD17: Asesor | AE17: Angie Benitez | AF17: Bogotá | AG17: Cundinamarca | AH17: PENDIENTE LINK | AJ17: NO
A18: 2024 | B18: 4 | C18: Abril | D18: 202400154 | E18: Apoyo Ciudadano | F18: Salud | G18: Citas médicas | H18: Diagnóstico: manguito tirador derecho Solicitud: cita con el cirujano para realizar cirugía Tiempo de solicitud: 9 meses | I18: Secretaría Distrital de Salud | J18: Carmelo | K18: Sur | L18: 08.Kennedy | M18: 08.Class | N18: =BUSCARX(R[0]C[-1],CONVENCIONES!R12C1:R42C1,CONVENCIONES!R12C2:R42C2) -> #ERROR! | O18: Gestión 2024 | P18: María Engracia Romero de Penagos | Q18: Mujer | R18: 28834677 | S18: carrera 87#57 a 09 sur | T18: 4.624477670996924, -74.18776833455878 | U18: alejandrarodriguezpenagos@hotmail.com | V18: 3114500159 | W18: Tramites | Y18: Finalizado | Z18: Positivo | AA18: N/A | AB18: 45406 | AC18: N/A | AD18: Asesor | AE18: Angie Benitez | AF18: Bogotá | AG18: Cundinamarca | AH18: PENDIENTE LINK | AJ18: NO
A19: 2024 | B19: 4 | C19: Abril | D19: 202400157 | E19: Apoyo Ciudadano | F19: Salud | G19: Procedimientos y exámenes | H19: Solicitud: Que le realicen los exámenes para generar el diagnostico, al paciente solo le indican bacterias o parasitos estomacales, le indicaron que podría ser cancer pero no le han realizado los exámenes correspondientes Tiempo de solicitud: 4 meses Nota: requiere atención porque presuntamente tiene síntomas cancerígenos sin embargo la EPS no le han dado las ordenes para los exámenes y descartar o confirmar esa circunstancia | I19: Secretaría Distrital de Salud | J19: Bosa Linda | K19: Sur | L19: 08.Kennedy | M19: 08.Class | N19: =BUSCARX(R[0]C[-1],CONVENCIONES!R12C1:R42C1,CONVENCIONES!R12C2:R42C2) -> #ERROR! | O19: Gestión 2024 | P19: José María Arango Reinosa | Q19: Hombre | R19: 79635982 | S19: Carrera 85 #55 - 29 | T19: 4.648494761362429, -74.14854919752344 | U19: doraba.arango1975@gmail.com | V19: 3118469096 | W19: Tramites | Y19: Finalizado | Z19: Positivo | AA19: N/A | AB19: 45406 | AC19: N/A | AD19: Asesor | AE19: Angie Benitez | AF19: Bogotá | AG19: Cundinamarca | AH19: PENDIENTE LINK | AJ19: NO
A20: 2024 | B20: 4 | C20: Abril | D20: 202400158 | E20: Apoyo Ciudadano | F20: Salud | G20: Citas médicas | H20: Solicitud: cita con oftalmología | I20: Secretaría Distrital de Salud | J20: Palenque | K20: Sur | L20: 08.Kennedy | M20: 08.Kennedy Central | N20: =BUSCARX(R[0]C[-1],CONVENCIONES!R12C1:R42C1,CONVENCIONES!R12C2:R42C2) -> #ERROR! | O20: Gestión 2024 | P20: Alis Peña de Chitiva | Q20: Mujer | R20: 41515508 | S20: cra 78 f # 42 c 04 sur | T20: 4.614946771581417, -74.15955886339442 | U20: juanchitiva@hotmail.com | V20: 3102502262 | W20: Tramites | Y20: Finalizado | Z20: Positivo | AA20: N/A | AB20: 45412 | AC20: N/A | AD20: Asesor | AE20: Angie Benitez | AF20: Bogotá | AG20: Cundinamarca | AH20: PENDIENTE LINK | AJ20: NO
A21: 2024 | B21: 4 | C21: Abril | D21: 202400159 | E21: Apoyo Ciudadano | F21: Salud | G21: Medicamentos | H21: Diagnóstico: trastornos mentales y del comportamiento debido a uso del tabaco: síndrome de dependencia Solicitud: La hna sufre de depresión y ansiedad, la EPS no le hace entrega de orden de medicamentos ya que no hay agenda con el psiquiatra; por lo cual el hijo debe llevarla de manera mensual a urgencias psiquiátricas para que le entreguen medicamentos por cada mes; se solicita cita y seguimiento con psiquiatría con el fin de que le hagan entrega de ordenes de medicamentos crónicos sin necesidad de asistir a urgencias Tiempo de solicitud: 4 meses | I21: Secretaría Distrital de Salud | J21: Pastranita | K21: Sur | L21: 08.Kennedy | M21: 08.Class | N21: =BUSCARX(R[0]C[-1],CONVENCIONES!R12C1:R42C1,CONVENCIONES!R12C2:R42C2) -> #ERROR! | O21: Gestión 2024 | P21: Nubia Rodriguez Mendez | Q21: Mujer | R21: 39749227 | S21: Transversal 78L ·50 sur -17 apto 401 | T21: 4.614045683632616, -74.16940289575687 | U21: richardjokerazul@gmail.com | V21: 3059293551 (Hno Ricardo - hijo) | W21: Tramites | Y21: Finalizado | Z21: Pendiente | AA21: Ya se asignó cita, faltarían los medicamentos. | AB21: 45412 | AC21: N/A | AD21: Asesor | AE21: Angie Benitez | AF21: Bogotá | AG21: Cundinamarca | AH21: PENDIENTE LINK | AJ21: NO
A22: 2024 | B22: 4 | C22: Abril | D22: 202400176 | E22: Apoyo Ciudadano | F22: Educación | H22: Cupo para el colegio Debora Arango Motivo: me gustaría el cambio del colegio ya que este Debora Arango me queda más cerca de mi residencia, que el colegio Romulo Gallego | I22: Secretaría de Educación del Distrito | J22: Roma | K22: Sur | L22: 08.Kennedy | M22: 08.Class | N22: =BUSCARX(R[0]C[-1],CONVENCIONES!R12C1:R42C1,CONVENCIONES!R12C2:R42C2) -> #ERROR! | O22: Gestión 2024 | P22: Mayelli Abonia Camacho Cedula: 29.507.889 Alanna Samai Cuesta Abonia Tarjeta de identidad 1.030.677.352 | Q22: Mujer | R22: 29.507.889 | S22: Calle 53a # 81i-21 sur | T22: 4.616576475077917, -74.17434200880973 | U22: mayaboca17@gmail.com | V22: 3147962210 | W22: Tramites | Y22: Finalizado | Z22: Positivo | AA22: Se hizo la gestión a través del DILE de Kennedy por medio de la edilesa | AB22: 45407 | AC22: 45422 | AD22: Asesor | AE22: Angie Benitez | AF22: Bogotá | AG22: Cundinamarca | AH22: PENDIENTE LINK | AJ22: NO
A23: 2024 | B23: 5 | C23: Mayo | D23: 202400179 | E23: Apoyo Ciudadano | F23: Salud | G23: Citas médicas | H23: Diagnóstico: enfermedad de Chagas aguda que afecta el corazón Solicitud; consulta de primera vez por especialista en cirugía cardiovascular. | I23: Secretaría Distrital de Salud | J23: Ciudad de Cali | K23: Sur | L23: 08.Kennedy | M23: 08.Kennedy Central | N23: =BUSCARX(R[0]C[-1],CONVENCIONES!R12C1:R42C1,CONVENCIONES!R12C2:R42C2) -> #ERROR! | O23: Gestión 2024 | P23: Celia Matilde Forero rojas Acudiente: Luz Marina Valenzuela | Q23: Mujer | R23: 28190396 | S23: Kra 86c bis #42 - 51 sur | T23: 4.633140133136534, -74.16639663455871 | U23: luzmari2909@hotmail.com | V23: 3213032240 / 3124310711 | W23: Tramites | X23: Interno | Y23: Finalizado | Z23: Positivo | AA23: N/A | AB23: 45427 | AC23: N/A | AD23: Asesor | AE23: Angie Benitez | AF23: Bogotá | AG23: Cundinamarca | AH23: PENDIENTE LINK | AJ23: NO
A24: 2024 | B24: 5 | C24: Mayo | D24: 202400181 | E24: Apoyo Ciudadano | F24: Salud | G24: Medicamentos | H24: Diagnóstico: hipertensa, sufre del corazón, tiroides , triglicedeos, catarata densa en los ojos. Solicitud: 1. medicamentos para hipertensión. 2. Cita con oftalmología. | I24: Secretaría Distrital de Salud | J24: Villa Nelly | K24: Sur | L24: 08.Kennedy | M24: 08.Kennedy Central | N24: =BUSCARX(R[0]C[-1],CONVENCIONES!R12C1:R42C1,CONVENCIONES!R12C2:R42C2) -> #ERROR! | O24: Gestión 2024 | P24: Otilia Sosa Gracia | Q24: Mujer | R24: 20858218 | S24: calle 42 g #80 b 21 sur | T24: 4.622008710619711, -74.16559977688753 | U24: elsyyg@gmail.com | V24: 3138010381 | W24: Tramites | X24: Interno | Y24: En Proceso | Z24: Pendiente | AA24: N/A | AB24: 45427 | AC24: N/A | AD24: Asesor | AE24: Angie Benitez | AF24: Bogotá | AG24: Cundinamarca | AH24: PENDIENTE LINK | AJ24: NO
A25: 2024 | B25: 5 | C25: Mayo | D25: 202400182 | E25: Apoyo Ciudadano | F25: Salud | G25: Citas médicas | H25: Diagnóstico: leve de Autismo, TDH elevada con hiperactiva. Solicitud puntual:Agilizar una cita con el especialista Neurólogo pediatra para que pueda revisar los exámenes examinar el niño y así obtener un diagnóstico definitivo, y acceder a un tratamiento. Tengo la orden desde septiembre 29 del 2023 y no asido posible la cita con el especialista por motivos de que hay agenda. Mi hijo tiene dificultades para adaptarse a los entornos sociales. | I25: Secretaría Distrital de Salud | J25: Carvajal | K25: Sur | L25: 08.Kennedy | M25: 08.Carvajal | N25: =BUSCARX(R[0]C[-1],CONVENCIONES!R12C1:R42C1,CONVENCIONES!R12C2:R42C2) -> #ERROR! | O25: Gestión 2024 | P25: Mateo Alejandro Díaz Montañez | Q25: Hombre | R25: 1023410547 | S25: CL 64 C SUR 27 13 CANDELARIA | T25: 4.615132307907278, -74.13793253984731 | U25: NA | V25: 3163437486 | W25: Tramites | X25: Interno | Y25: En Proceso | Z25: Pendiente | AA25: N/A | AB25: 45427 | AC25: N/A | AD25: Asesor | AE25: Angie Benitez | AF25: Bogotá | AG25: Cundinamarca | AH25: PENDIENTE LINK | AJ25: NO
A26: 2024 | B26: 5 | C26: Mayo | D26: 202400284 | E26: Apoyo Ciudadano | F26: Salud | H26: Solicita una cita con el Fisiatra, una con el Endocrinólogo y otra cirugía oral – Odontólogo | I26: Secretaría Distrital de Salud | J26: Santa Sofía | K26: Sur | L26: 08.Kennedy | M26: 08.Patio Bonito | N26: =BUSCARX(R[0]C[-1],CONVENCIONES!R12C1:R42C1,CONVENCIONES!R12C2:R42C2) -> #ERROR! | O26: Gestión 2024 | P26: Digna María Vargas de Castillo | Q26: Mujer | R26: 26533998 | S26: Cra 29A # 75-30 | T26: 4.622839368592367, -74.08538886819075 | U26: hanavicolombia@gmail.com | V26: 3108548307 | W26: Tramites | X26: Interno | Y26: Finalizado | Z26: Positivo | AA26: Se programo la cita correspondiente | AB26: 45439 | AC26: 45449 | AD26: Asesor | AE26: Fernando Zamora | AF26: Bogotá | AG26: Cundinamarca | AH26: 202400284_Digna María Vargas de Castillo | AJ26: NO
A27: 2024 | B27: 5 | C27: Mayo | D27: 202400285 | E27: Apoyo Ciudadano | F27: Salud | H27: Solicita una cita con Endocrinólogo | I27: Secretaría Distrital de Salud | J27: Santa Sofía | K27: Sur | L27: 08.Kennedy | M27: 08.Patio Bonito | N27: =BUSCARX(R[0]C[-1],CONVENCIONES!R12C1:R42C1,CONVENCIONES!R12C2:R42C2) -> #ERROR! | O27: Gestión 2024 | P27: José Nicolás Castillo Moreno | Q27: Hombre | R27: 19244568 | S27: Cra 29A # 75-30 | T27: 4.622839368592367, -74.08538886819075 | U27: hanavicolombia@gmail.com | V27: 3108548307 | W27: Tramites | X27: Interno | Y27: Finalizado | Z27: Positivo | AA27: Se programo la cita correspondiente | AB27: 45439 | AC27: 45449 | AD27: Asesor | AE27: Fernando Zamora | AF27: Bogotá | AG27: Cundinamarca | AH27: 202400285_José Nicolás Castillo Moreno | AJ27: NO
A28: 2024 | B28: 5 | C28: Mayo | D28: 202400292 | E28: Apoyo Ciudadano | F28: Salud | G28: Tratamientos | H28: Diagnóstico: cáncer de mama Solicitud : recibir la tercer quimioterapia en el tiempo estipulado por el oncólogo. | I28: Superintendencia de Salud | J28: Villa Alsacia | K28: Sur | L28: 08.Kennedy | M28: N/A | N28: =BUSCARX(R[0]C[-1],CONVENCIONES!R12C1:R42C1,CONVENCIONES!R12C2:R42C2) -> #ERROR! | O28: Gestión 2024 | P28: Margarita López Ramírez | Q28: Mujer | R28: 52734656 | S28: carrera 72 A bis A #11B - 27 | T28: 4.644586969759896, -74.13433423455866 | U28: mlopezr1@educacionbogota.edu.co | V28: 3057519590 | W28: Tramites | Y28: Finalizado | Z28: Positivo | AA28: La persona también hizo gestión por su parte | AB28: 45433 | AC28: 45440 | AD28: Asesor | AE28: Angie Benitez | AF28: Bogotá | AG28: Cundinamarca | AH28: PENDIENTE LINK | AJ28: NO
A29: 2024 | B29: 6 | C29: Junio | D29: 202400382 | E29: Apoyo Ciudadano | F29: Salud | H29: El ciudadano Álvaro Silva Castro indica que no le han entregado un medicamento indispensable para mejorar su salud | I29: Secretaría Distrital de Salud | J29: Patio Bonito | K29: Sur | L29: 08.Kennedy | M29: 08.Patio Bonito | N29: =BUSCARX(R[0]C[-1],CONVENCIONES!R12C1:R42C1,CONVENCIONES!R12C2:R42C2) -> #ERROR! | O29: Gestión 2024 | P29: Álvaro Silva Castro | Q29: Hombre | R29: 14269252 | S29: Calle 8a#92-71 | T29: 4.655349208446909, -74.1568137619685 | U29: alvarosilva7@hotmail.com | V29: 3133683676 | W29: Tramites | X29: Interno | Y29: Finalizado | Z29: Positivo | AA29: Se hace traslado a la entidad | AB29: 45468 | AC29: =DIA.LAB(R[0]C[-1],15) -> #ERROR! | AD29: Asesor | AE29: Fernando Zamora | AF29: Bogotá | AG29: Cundinamarca | AH29: 202400382_Álvaro Silva Castro | AJ29: NO
A30: 2024 | B30: 7 | C30: Julio | D30: 202400416 | E30: Apoyo Ciudadano | F30: Salud | G30: Citas médicas | H30: Traslado caso de paciente con catarata requiere cita de oftalmología | I30: Secretaría Distrital de Salud | J30: Las Margaritas | K30: Sur | L30: 08.Kennedy | M30: 07.Bosa Recreo | N30: =BUSCARX(R[0]C[-1],CONVENCIONES!R12C1:R42C1,CONVENCIONES!R12C2:R42C2) -> #ERROR! | O30: Gestión 2024 | P30: Cleotilde Sanabria | Q30: Mujer | R30: 20285203 | S30: Calle 48 Sur 88C-49 | T30: 4.6317774265560585, -74.17887255569696 | U30: cleotildesanabriagonzales@gmail.com | V30: 3102099828 | W30: Tramites | X30: Interno | Y30: Finalizado | Z30: Positivo | AA30: Se asigna cita médica | AB30: 45475 | AC30: N/A | AD30: Asesor | AE30: Maicol Quiroga | AF30: Bogotá | AG30: Cundinamarca | AH30: Cleotilde Sanabria | AJ30: NO
A31: 2024 | B31: 7 | C31: Julio | D31: 202400422 | E31: Apoyo Ciudadano | F31: Salud | H31: Solicita una cita con especialista por dolor constante en la espalda desde hace 3 meses | I31: Secretaría Distrital de Salud | J31: Altamar | K31: Sur | L31: 08.Kennedy | M31: 08.Patio Bonito | N31: =BUSCARX(R[0]C[-1],CONVENCIONES!R12C1:R42C1,CONVENCIONES!R12C2:R42C2) -> #ERROR! | O31: Gestión 2024 | P31: Rita Leonor Sánchez Gonzales | Q31: Mujer | R31: 23486496 | S31: Cl. 42b Sur #87i-20 | T31: 4.63471293116785, -74.17096643390632 | U31: jazmincilla@hotmail.es | V31: 3114738322 | W31: Tramites | X31: Interno | Y31: Finalizado | Z31: Positivo | AA31: Se programa la cita solicitada | AB31: 45477 | AC31: N/A | AD31: Asesor | AE31: Fernando Zamora | AF31: Bogotá | AG31: Cundinamarca | AH31: 202400422_Rita Leonor Sánchez Gonzales | AJ31: NO
A32: 2024 | B32: 7 | C32: Julio | D32: 202400423 | E32: Apoyo Ciudadano | F32: Educación | H32: Solcita información sobre el proceso de admisión de su hijo en la universidad distrital y la agencia Atenea | I32: Secretaría de Educación del Distrito | J32: Calarca | K32: Sur | L32: 08.Kennedy | M32: 08.Class | N32: =BUSCARX(R[0]C[-1],CONVENCIONES!R12C1:R42C1,CONVENCIONES!R12C2:R42C2) -> #ERROR! | O32: Gestión 2024 | P32: Kelly Cecilia Boya Escobar | Q32: Mujer | R32: 67041434 | S32: cll. 47 # 80 - 56 | T32: 4.619868541173852, -74.16889470515919 | U32: kellyboya0112@gmail.com | V32: 3182990558 | W32: Tramites | X32: Interno | Y32: Finalizado | Z32: Negativo | AA32: La respuesta a la petición fue negativa, ya que indica que no aplica al proceso satisfactoriamente y que debe hacer el proceso cuando hayan nuevas convocatorias | AB32: 45477 | AC32: N/A | AD32: Asesor | AE32: Fernando Zamora | AF32: Bogotá | AG32: Cundinamarca | AH32: 202400423_Kelly Cecilia Boya Escobar | AJ32: NO
A33: 2024 | B33: 7 | C33: Julio | D33: 202400432 | E33: Apoyo Ciudadano | F33: Salud | G33: Procedimientos y exámenes | H33: Caso salud: - Electrocardiograma de ritmo o de superficie. - Consulta por primera vez por optometría. | I33: Superintendencia de Salud | J33: Palenque | K33: Sur | L33: 08.Kennedy | M33: 08.Kennedy Central | N33: =BUSCARX(R[0]C[-1],CONVENCIONES!R12C1:R42C1,CONVENCIONES!R12C2:R42C2) -> #ERROR! | O33: Gestión 2024 | P33: Ana Teresa Vargas Florez | Q33: Mujer | R33: 27876793 | S33: Calle 42f #78c 03 | T33: 4.613273106566682, -74.16032417657928 | U33: anateresavargas0124@gmail.com | V33: celular: 3015584177 - 3152405466 (hermano de la paciente). | W33: Tramites | X33: Interno | Y33: En Proceso | Z33: Pendiente | AA33: Se hace el traslado a la entidad a través de oficio | AB33: 45481 | AC33: N/A | AD33: Asesor | AE33: Angie Benitez | AF33: Bogotá | AG33: Cundinamarca | AH33: PENDIENTE LINK | AJ33: NO
A34: 2024 | B34: 7 | C34: Julio | D34: 202400441 | E34: Apoyo Ciudadano | F34: Servicio militar | H34: Asesoría para obtener la libreta militar | I34: Secretaría Distrital de Seguridad, Convivencia y Justicia | J34: Ayacucho II sector | K34: Sur | L34: 08.Kennedy | M34: 08.Kennedy Central | N34: =BUSCARX(R[0]C[-1],CONVENCIONES!R12C1:R42C1,CONVENCIONES!R12C2:R42C2) -> #ERROR! | O34: Gestión 2024 | P34: Jorge Enrique Alba Balaguera | Q34: Hombre | R34: 1022430676 | S34: CRA 78p bis #6-35sur | T34: 4.62934032753972, -74.1510866900773 | U34: joalba2748@gmail.com | V34: 313 4256455 | W34: Tramites | X34: N/A | Y34: Finalizado | Z34: Positivo | AA34: Es un referido | AB34: 45483 | AC34: N/A | AD34: Asesor | AE34: Angie Benitez | AF34: Bogotá | AG34: Cundinamarca | AH34: PENDIENTE LINK | AJ34: NO
A35: 2024 | B35: 7 | C35: Julio | D35: 202400449 | E35: Apoyo Ciudadano | F35: Salud | H35: Solicitud de cita para paciente con cancer | I35: Secretaría Distrital de Salud | J35: Patio Bonito | K35: Sur | L35: 08.Kennedy | M35: 08.Patio Bonito | N35: =BUSCARX(R[0]C[-1],CONVENCIONES!R12C1:R42C1,CONVENCIONES!R12C2:R42C2) -> #ERROR! | O35: Gestión 2024 | P35: Henry Enrique Herrera Molina | Q35: Hombre | R35: 79713798 | S35: Cra 89c # 38d 19 sur | T35: 4.639966868831216, -74.16820810362483 | U35: henryh_m@hotmail.com | V35: 3143908862 | W35: Tramites | X35: Interno | Y35: Finalizado | Z35: Positivo | AA35: Se hace el traslado a la entidad | AB35: 45484 | AC35: N/A | AD35: Asesor | AE35: Fernando Zamora | AF35: Bogotá | AG35: Cundinamarca | AH35: 202400449_Henry Enrique Herrera Molina | AJ35: NO
